{
	"schema_version": "1.6.0",
	"id": "GHSA-f6f8-9mx6-9mx2",
	"modified": "2024-08-02T16:09:53.414109Z",
	"published": "2024-07-10T06:33:52Z",
	"aliases": [
		"CVE-2024-39614",
		"PYSEC-2024-59"
	],
	"related": [
		"CGA-p589-84hv-6jc4"
	],
	"summary": "Django vulnerable to Denial of Service",
	"details": "An issue was discovered in Django 5.0 before 5.0.7 and 4.2 before 4.2.14. `get_supported_language_variant()` was subject to a potential denial-of-service attack when used with very long strings containing specific characters.",
	"severity": [
		{
			"type": "CVSS_V3",
			"score": "CVSS:3.1/AV:N/AC:L/PR:N/UI:N/S:U/C:N/I:N/A:H"
		},
		{
			"type": "CVSS_V4",
			"score": "CVSS:4.0/AV:N/AC:L/AT:N/PR:N/UI:N/VC:N/VI:N/VA:H/SC:N/SI:N/SA:N"
		}
	],
	"affected": [
		{
			"package": {
				"ecosystem": "PyPI",
				"name": "django",
				"purl": "pkg:pypi/django"
			},
			"ranges": [
				{
					"type": "ECOSYSTEM",
					"events": [
						{
							"introduced": "5.0"
						},
						{
							"fixed": "5.0.7"
						}
					]
				}
			],
			"versions": [
				"5.0",
				"5.0.1",
				"5.0.2",
				"5.0.3",
				"5.0.4",
				"5.0.5",
				"5.0.6"
			],
			"database_specific": {
				"source": "https://github.com/github/advisory-database/blob/main/advisories/github-reviewed/2024/07/GHSA-f6f8-9mx6-9mx2/GHSA-f6f8-9mx6-9mx2.json"
			}
		},
		{
			"package": {
				"ecosystem": "PyPI",
				"name": "django",
				"purl": "pkg:pypi/django"
			},
			"ranges": [
				{
					"type": "ECOSYSTEM",
					"events": [
						{
							"introduced": "4.2"
						},
						{
							"fixed": "4.2.14"
						}
					]
				}
			],
			"versions": [
				"4.2",
				"4.2.1",
				"4.2.10",
				"4.2.11",
				"4.2.12",
				"4.2.13",
				"4.2.2",
				"4.2.3",
				"4.2.4",
				"4.2.5",
				"4.2.6",
				"4.2.7",
				"4.2.8",
				"4.2.9"
			],
			"database_specific": {
				"source": "https://github.com/github/advisory-database/blob/main/advisories/github-reviewed/2024/07/GHSA-f6f8-9mx6-9mx2/GHSA-f6f8-9mx6-9mx2.json"
			}
		}
	],
	"references": [
		{
			"type": "ADVISORY",
			"url": "https://nvd.nist.gov/vuln/detail/CVE-2024-39614"
		},
		{
			"type": "WEB",
			"url": "https://github.com/django/django/commit/17358fb35fb7217423d4c4877ccb6d1a3a40b1c3"
		},
		{
			"type": "WEB",
			"url": "https://github.com/django/django/commit/8e7a44e4bec0f11474699c3111a5e0a45afe7f49"
		},
		{
			"type": "WEB",
			"url": "https://docs.djangoproject.com/en/dev/releases/security"
		},
		{
			"type": "PACKAGE",
			"url": "https://github.com/django/django"
		},
		{
			"type": "WEB",
			"url": "https://github.com/pypa/advisory-database/tree/main/vulns/django/PYSEC-2024-59.yaml"
		},
		{
			"type": "WEB",
			"url": "https://groups.google.com/forum/#%21forum/django-announce"
		},
		{
			"type": "WEB",
			"url": "https://www.djangoproject.com/weblog/2024/jul/09/security-releases"
		}
	],
	"database_specific": {
		"cwe_ids": [
			"CWE-130",
			"CWE-770"
		],
		"github_reviewed": true,
		"github_reviewed_at": "2024-07-10T21:43:25Z",
		"nvd_published_at": "2024-07-10T05:15:12Z",
		"severity": "HIGH"
	}
}
