{
	"schema_version": "1.6.0",
	"id": "MAL-2024-5467",
	"modified": "2024-06-28T03:14:56.973387Z",
	"published": "2024-06-25T13:38:04Z",
	"aliases": [
		"SNYK-PYTHON-PILKOW-6513370"
	],
	"summary": "Malicious code in pilkow (PyPI)",
	"details": "\n---\n_-= Per source details. Do not edit below this line.=-_\n",
	"affected": [
		{
			"package": {
				"ecosystem": "PyPI",
				"name": "pilkow",
				"purl": "pkg:pypi/pilkow"
			},
			"versions": [
				"1.0.0"
			],
			"database_specific": {
				"source": "https://github.com/ossf/malicious-packages/blob/main/osv/malicious/pypi/pilkow/MAL-2024-5467.json"
			}
		}
	],
	"references": [
		{
			"type": "ARTICLE",
			"url": "https://medium.com/checkmarx-security/pypi-is-under-attack-project-creation-and-user-registration-suspended-heres-the-details-c3b6291d4579"
		},
		{
			"type": "ADVISORY",
			"url": "https://security.snyk.io/vuln/SNYK-PYTHON-PILKOW-6513370"
		}
	],
	"credits": [
		{
			"name": "ReversingLabs",
			"contact": [
				"https://www.reversinglabs.com"
			],
			"type": "FINDER"
		}
	],
	"database_specific": {
		"malicious-packages-origins": [
			{
				"id": "RLMA-2024-04249",
				"import_time": "2024-06-28T02:49:37.877401067Z",
				"modified_time": "2024-06-25T13:38:04Z",
				"sha256": "effb09467a0e0e949195ea5a48d7d041b5e5e399d977cb352056cd95925a2216",
				"source": "reversing-labs",
				"versions": [
					"1.0.0"
				]
			}
		]
	}
}
