{
	"schema_version": "1.6.0",
	"id": "MAL-2024-4863",
	"modified": "2024-10-24T01:01:58Z",
	"published": "2024-06-25T13:33:11Z",
	"aliases": [
		"SNYK-PYTHON-CAPMONSTERCLOUDCLIET-6513711"
	],
	"summary": "Malicious code in capmonstercloudcliet (PyPI)",
	"details": "\n---\n_-= Per source details. Do not edit below this line.=-_\n",
	"affected": [
		{
			"package": {
				"ecosystem": "PyPI",
				"name": "capmonstercloudcliet",
				"purl": "pkg:pypi/capmonstercloudcliet"
			},
			"versions": [
				"1.0.0"
			],
			"database_specific": {
				"source": "https://github.com/ossf/malicious-packages/blob/main/osv/malicious/pypi/capmonstercloudcliet/MAL-2024-4863.json"
			}
		}
	],
	"references": [
		{
			"type": "ARTICLE",
			"url": "https://medium.com/checkmarx-security/pypi-is-under-attack-project-creation-and-user-registration-suspended-heres-the-details-c3b6291d4579"
		},
		{
			"type": "ADVISORY",
			"url": "https://security.snyk.io/vuln/SNYK-PYTHON-CAPMONSTERCLOUDCLIET-6513711"
		}
	],
	"credits": [
		{
			"name": "ReversingLabs",
			"contact": [
				"https://www.reversinglabs.com"
			],
			"type": "FINDER"
		}
	],
	"database_specific": {
		"malicious-packages-origins": [
			{
				"id": "RLMA-2024-03643",
				"import_time": "2024-06-28T02:48:26.9179834Z",
				"modified_time": "2024-06-25T13:33:11Z",
				"sha256": "f1662d2fa1f65f6995ba31ee245d636c8759b82fc8f0bb2eca3832f4656f7d35",
				"source": "reversing-labs",
				"versions": [
					"1.0.0"
				]
			},
			{
				"id": "RLUA-2024-07931",
				"import_time": "2024-10-24T00:58:53.017098959Z",
				"modified_time": "2024-10-16T14:37:33Z",
				"sha256": "ce4fbace56ca1970af6939c42f4f8f021afad6f33b559f5dd20b6421e65689ea",
				"source": "reversing-labs"
			}
		]
	}
}
