{
	"schema_version": "1.6.0",
	"id": "MAL-2024-5469",
	"modified": "2024-10-24T01:01:58Z",
	"published": "2024-06-25T13:38:05Z",
	"aliases": [
		"SNYK-PYTHON-PILLIOW-6513407"
	],
	"summary": "Malicious code in pilliow (PyPI)",
	"details": "\n---\n_-= Per source details. Do not edit below this line.=-_\n",
	"affected": [
		{
			"package": {
				"ecosystem": "PyPI",
				"name": "pilliow",
				"purl": "pkg:pypi/pilliow"
			},
			"versions": [
				"1.0.0"
			],
			"database_specific": {
				"source": "https://github.com/ossf/malicious-packages/blob/main/osv/malicious/pypi/pilliow/MAL-2024-5469.json"
			}
		}
	],
	"references": [
		{
			"type": "ADVISORY",
			"url": "https://security.snyk.io/vuln/SNYK-PYTHON-PILLIOW-6513407"
		},
		{
			"type": "ARTICLE",
			"url": "https://medium.com/checkmarx-security/pypi-is-under-attack-project-creation-and-user-registration-suspended-heres-the-details-c3b6291d4579"
		}
	],
	"credits": [
		{
			"name": "ReversingLabs",
			"contact": [
				"https://www.reversinglabs.com"
			],
			"type": "FINDER"
		}
	],
	"database_specific": {
		"malicious-packages-origins": [
			{
				"id": "RLMA-2024-04251",
				"import_time": "2024-06-28T02:49:38.085262949Z",
				"modified_time": "2024-06-25T13:38:05Z",
				"sha256": "906e059c9901566c60c18c26de93bd8e419d35100ad2076639939c619e204d72",
				"source": "reversing-labs",
				"versions": [
					"1.0.0"
				]
			},
			{
				"id": "RLUA-2024-08679",
				"import_time": "2024-10-24T00:59:34.788422666Z",
				"modified_time": "2024-10-16T14:45:22Z",
				"sha256": "fa13ccc4c0ced06e4f9da0e568673d68934d7d98519534d3421503c84d01cdeb",
				"source": "reversing-labs"
			}
		]
	}
}
