{
	"schema_version": "1.6.0",
	"id": "MAL-2024-5605",
	"modified": "2024-10-24T01:01:59Z",
	"published": "2024-06-25T13:39:10Z",
	"aliases": [
		"SNYK-PYTHON-PYCORDF-6513531"
	],
	"summary": "Malicious code in py-cordf (PyPI)",
	"details": "\n---\n_-= Per source details. Do not edit below this line.=-_\n",
	"affected": [
		{
			"package": {
				"ecosystem": "PyPI",
				"name": "py-cordf",
				"purl": "pkg:pypi/py-cordf"
			},
			"versions": [
				"1.0.0"
			],
			"database_specific": {
				"source": "https://github.com/ossf/malicious-packages/blob/main/osv/malicious/pypi/py-cordf/MAL-2024-5605.json"
			}
		}
	],
	"references": [
		{
			"type": "ARTICLE",
			"url": "https://medium.com/checkmarx-security/pypi-is-under-attack-project-creation-and-user-registration-suspended-heres-the-details-c3b6291d4579"
		},
		{
			"type": "ADVISORY",
			"url": "https://security.snyk.io/vuln/SNYK-PYTHON-PYCORDF-6513531"
		}
	],
	"credits": [
		{
			"name": "ReversingLabs",
			"contact": [
				"https://www.reversinglabs.com"
			],
			"type": "FINDER"
		}
	],
	"database_specific": {
		"malicious-packages-origins": [
			{
				"id": "RLMA-2024-04387",
				"import_time": "2024-06-28T02:49:54.246690751Z",
				"modified_time": "2024-06-25T13:39:10Z",
				"sha256": "baf6db8c16538643f46258bd64f3c9a753e2b857523d65f8cc19bd96899af855",
				"source": "reversing-labs",
				"versions": [
					"1.0.0"
				]
			},
			{
				"id": "RLUA-2024-08820",
				"import_time": "2024-10-24T00:59:43.978305326Z",
				"modified_time": "2024-10-16T14:46:48Z",
				"sha256": "3ae4c05d6fd67bcbcaff03f737f76df82c1cdab4d0a8461625f0ec02efef5187",
				"source": "reversing-labs"
			}
		]
	}
}
